{
  DataVersion:3953,
  size:[
    13,
    6,
    20
  ],
  palette:[
    {
      Name:"minecraft:redstone_block"
    },
    {
      Name:"minecraft:light_gray_wool"
    },
    {
      Name:"minecraft:smooth_quartz"
    },
    {
      Name:"minecraft:quartz_block"
    },
    {
      Name:"minecraft:acacia_planks"
    },
    {
      Properties:{
        axis:"y"
      },
      Name:"minecraft:stripped_cherry_log"
    },
    {
      Properties:{
        axis:"y"
      },
      Name:"minecraft:stripped_oak_log"
    },
    {
      Name:"minecraft:white_terracotta"
    },
    {
      Name:"minecraft:black_wool"
    },
    {
      Name:"minecraft:air"
    },
    {
      Properties:{
        face:"wall",
        powered:"false",
        facing:"south"
      },
      Name:"minecraft:oak_button"
    },
    {
      Properties:{
        facing:"up",
        extended:"true"
      },
      Name:"minecraft:piston"
    },
    {
      Name:"minecraft:light_blue_carpet"
    },
    {
      Properties:{
        half:"bottom",
        waterlogged:"false",
        shape:"straight",
        facing:"south"
      },
      Name:"minecraft:smooth_sandstone_stairs"
    },
    {
      Name:"minecraft:white_carpet"
    },
    {
      Properties:{
        half:"bottom",
        waterlogged:"false",
        shape:"straight",
        facing:"north"
      },
      Name:"minecraft:smooth_sandstone_stairs"
    },
    {
      Properties:{
        hinge:"right",
        half:"lower",
        powered:"false",
        facing:"south",
        open:"false"
      },
      Name:"minecraft:cherry_door"
    },
    {
      Properties:{
        waterlogged:"false",
        type:"bottom"
      },
      Name:"minecraft:acacia_slab"
    },
    {
      Properties:{
        half:"bottom",
        waterlogged:"false",
        powered:"false",
        facing:"west",
        open:"true"
      },
      Name:"minecraft:acacia_trapdoor"
    },
    {
      Properties:{
        half:"bottom",
        waterlogged:"false",
        powered:"false",
        facing:"north",
        open:"true"
      },
      Name:"minecraft:acacia_trapdoor"
    },
    {
      Properties:{
        waterlogged:"false",
        type:"top"
      },
      Name:"minecraft:acacia_slab"
    },
    {
      Properties:{
        half:"bottom",
        waterlogged:"false",
        powered:"false",
        facing:"south",
        open:"true"
      },
      Name:"minecraft:acacia_trapdoor"
    },
    {
      Properties:{
        half:"bottom",
        waterlogged:"false",
        shape:"straight",
        facing:"north"
      },
      Name:"minecraft:oak_stairs"
    },
    {
      Properties:{
        facing:"up",
        short:"false",
        type:"normal"
      },
      Name:"minecraft:piston_head"
    },
    {
      Properties:{
        half:"bottom",
        waterlogged:"false",
        shape:"straight",
        facing:"south"
      },
      Name:"minecraft:oak_stairs"
    },
    {
      Properties:{
        half:"bottom",
        waterlogged:"false",
        powered:"false",
        facing:"east",
        open:"true"
      },
      Name:"minecraft:acacia_trapdoor"
    },
    {
      Properties:{
        half:"top",
        waterlogged:"false",
        shape:"straight",
        facing:"north"
      },
      Name:"minecraft:acacia_stairs"
    },
    {
      Properties:{
        half:"top",
        waterlogged:"false",
        shape:"straight",
        facing:"south"
      },
      Name:"minecraft:acacia_stairs"
    },
    {
      Properties:{
        hinge:"right",
        half:"upper",
        powered:"false",
        facing:"south",
        open:"false"
      },
      Name:"minecraft:cherry_door"
    },
    {
      Name:"minecraft:potted_flowering_azalea_bush"
    },
    {
      Properties:{
        lit:"false"
      },
      Name:"minecraft:orange_candle_cake"
    },
    {
      Properties:{
        half:"bottom",
        waterlogged:"false",
        powered:"false",
        facing:"south",
        open:"true"
      },
      Name:"minecraft:cherry_trapdoor"
    },
    {
      Properties:{
        half:"bottom",
        waterlogged:"false",
        powered:"false",
        facing:"west",
        open:"false"
      },
      Name:"minecraft:iron_trapdoor"
    },
    {
      Properties:{
        conditional:"false",
        facing:"south"
      },
      Name:"minecraft:command_block"
    },
    {
      Properties:{
        waterlogged:"false",
        facing:"east",
        type:"left"
      },
      Name:"minecraft:chest"
    },
    {
      Properties:{
        waterlogged:"false",
        facing:"east",
        type:"right"
      },
      Name:"minecraft:chest"
    },
    {
      Properties:{
        slot_2_occupied:"false",
        slot_5_occupied:"false",
        slot_4_occupied:"false",
        slot_0_occupied:"false",
        facing:"south",
        slot_1_occupied:"false",
        slot_3_occupied:"false"
      },
      Name:"minecraft:chiseled_bookshelf"
    },
    {
      Properties:{
        waterlogged:"false",
        facing:"west"
      },
      Name:"minecraft:oak_wall_sign"
    },
    {
      Properties:{
        waterlogged:"false",
        facing:"east"
      },
      Name:"minecraft:oak_wall_sign"
    },
    {
      Properties:{
        part:"head",
        facing:"north",
        occupied:"false"
      },
      Name:"minecraft:white_bed"
    },
    {
      Properties:{
        part:"foot",
        facing:"north",
        occupied:"false"
      },
      Name:"minecraft:white_bed"
    }
  ],
  blocks:[
    {
      pos:[
        9,
        0,
        9
      ],
      state:0
    },
    {
      pos:[
        9,
        0,
        10
      ],
      state:0
    },
    {
      pos:[
        10,
        0,
        9
      ],
      state:0
    },
    {
      pos:[
        10,
        0,
        10
      ],
      state:0
    },
    {
      pos:[
        0,
        1,
        1
      ],
      state:1
    },
    {
      pos:[
        0,
        1,
        2
      ],
      state:1
    },
    {
      pos:[
        0,
        1,
        3
      ],
      state:1
    },
    {
      pos:[
        0,
        1,
        4
      ],
      state:1
    },
    {
      pos:[
        0,
        1,
        5
      ],
      state:1
    },
    {
      pos:[
        0,
        1,
        6
      ],
      state:1
    },
    {
      pos:[
        0,
        1,
        7
      ],
      state:1
    },
    {
      pos:[
        0,
        1,
        8
      ],
      state:1
    },
    {
      pos:[
        0,
        1,
        9
      ],
      state:1
    },
    {
      pos:[
        0,
        1,
        10
      ],
      state:1
    },
    {
      pos:[
        0,
        1,
        11
      ],
      state:1
    },
    {
      pos:[
        0,
        1,
        12
      ],
      state:1
    },
    {
      pos:[
        0,
        1,
        13
      ],
      state:1
    },
    {
      pos:[
        0,
        1,
        14
      ],
      state:1
    },
    {
      pos:[
        0,
        1,
        15
      ],
      state:1
    },
    {
      pos:[
        0,
        1,
        16
      ],
      state:1
    },
    {
      pos:[
        0,
        1,
        17
      ],
      state:1
    },
    {
      pos:[
        0,
        1,
        18
      ],
      state:1
    },
    {
      pos:[
        0,
        1,
        19
      ],
      state:1
    },
    {
      pos:[
        1,
        1,
        0
      ],
      state:1
    },
    {
      pos:[
        1,
        1,
        1
      ],
      state:1
    },
    {
      pos:[
        1,
        1,
        2
      ],
      state:1
    },
    {
      pos:[
        1,
        1,
        3
      ],
      state:1
    },
    {
      pos:[
        1,
        1,
        4
      ],
      state:1
    },
    {
      pos:[
        1,
        1,
        5
      ],
      state:1
    },
    {
      pos:[
        1,
        1,
        6
      ],
      state:1
    },
    {
      pos:[
        1,
        1,
        7
      ],
      state:1
    },
    {
      pos:[
        1,
        1,
        8
      ],
      state:1
    },
    {
      pos:[
        1,
        1,
        9
      ],
      state:1
    },
    {
      pos:[
        1,
        1,
        10
      ],
      state:1
    },
    {
      pos:[
        1,
        1,
        11
      ],
      state:1
    },
    {
      pos:[
        1,
        1,
        12
      ],
      state:1
    },
    {
      pos:[
        1,
        1,
        13
      ],
      state:1
    },
    {
      pos:[
        1,
        1,
        14
      ],
      state:1
    },
    {
      pos:[
        1,
        1,
        15
      ],
      state:1
    },
    {
      pos:[
        1,
        1,
        16
      ],
      state:1
    },
    {
      pos:[
        1,
        1,
        17
      ],
      state:1
    },
    {
      pos:[
        1,
        1,
        18
      ],
      state:1
    },
    {
      pos:[
        1,
        1,
        19
      ],
      state:1
    },
    {
      pos:[
        2,
        1,
        0
      ],
      state:1
    },
    {
      pos:[
        2,
        1,
        1
      ],
      state:1
    },
    {
      pos:[
        2,
        1,
        2
      ],
      state:1
    },
    {
      pos:[
        2,
        1,
        3
      ],
      state:1
    },
    {
      pos:[
        2,
        1,
        4
      ],
      state:1
    },
    {
      pos:[
        2,
        1,
        5
      ],
      state:1
    },
    {
      pos:[
        2,
        1,
        6
      ],
      state:1
    },
    {
      pos:[
        2,
        1,
        7
      ],
      state:1
    },
    {
      pos:[
        2,
        1,
        8
      ],
      state:1
    },
    {
      pos:[
        2,
        1,
        9
      ],
      state:1
    },
    {
      pos:[
        2,
        1,
        10
      ],
      state:1
    },
    {
      pos:[
        2,
        1,
        11
      ],
      state:1
    },
    {
      pos:[
        2,
        1,
        12
      ],
      state:1
    },
    {
      pos:[
        2,
        1,
        13
      ],
      state:1
    },
    {
      pos:[
        2,
        1,
        14
      ],
      state:1
    },
    {
      pos:[
        2,
        1,
        15
      ],
      state:1
    },
    {
      pos:[
        2,
        1,
        16
      ],
      state:1
    },
    {
      pos:[
        2,
        1,
        17
      ],
      state:1
    },
    {
      pos:[
        2,
        1,
        18
      ],
      state:1
    },
    {
      pos:[
        2,
        1,
        19
      ],
      state:1
    },
    {
      pos:[
        3,
        1,
        0
      ],
      state:1
    },
    {
      pos:[
        3,
        1,
        1
      ],
      state:1
    },
    {
      pos:[
        3,
        1,
        2
      ],
      state:1
    },
    {
      pos:[
        3,
        1,
        3
      ],
      state:1
    },
    {
      pos:[
        3,
        1,
        4
      ],
      state:1
    },
    {
      pos:[
        3,
        1,
        5
      ],
      state:1
    },
    {
      pos:[
        3,
        1,
        6
      ],
      state:1
    },
    {
      pos:[
        3,
        1,
        7
      ],
      state:1
    },
    {
      pos:[
        3,
        1,
        8
      ],
      state:1
    },
    {
      pos:[
        3,
        1,
        9
      ],
      state:1
    },
    {
      pos:[
        3,
        1,
        10
      ],
      state:1
    },
    {
      pos:[
        3,
        1,
        11
      ],
      state:1
    },
    {
      pos:[
        3,
        1,
        12
      ],
      state:1
    },
    {
      pos:[
        3,
        1,
        13
      ],
      state:1
    },
    {
      pos:[
        3,
        1,
        14
      ],
      state:1
    },
    {
      pos:[
        3,
        1,
        15
      ],
      state:1
    },
    {
      pos:[
        3,
        1,
        16
      ],
      state:1
    },
    {
      pos:[
        3,
        1,
        17
      ],
      state:1
    },
    {
      pos:[
        3,
        1,
        18
      ],
      state:1
    },
    {
      pos:[
        3,
        1,
        19
      ],
      state:1
    },
    {
      pos:[
        4,
        1,
        0
      ],
      state:1
    },
    {
      pos:[
        4,
        1,
        1
      ],
      state:1
    },
    {
      pos:[
        4,
        1,
        2
      ],
      state:1
    },
    {
      pos:[
        4,
        1,
        3
      ],
      state:1
    },
    {
      pos:[
        4,
        1,
        4
      ],
      state:1
    },
    {
      pos:[
        4,
        1,
        5
      ],
      state:1
    },
    {
      pos:[
        4,
        1,
        6
      ],
      state:1
    },
    {
      pos:[
        4,
        1,
        7
      ],
      state:1
    },
    {
      pos:[
        4,
        1,
        8
      ],
      state:1
    },
    {
      pos:[
        4,
        1,
        9
      ],
      state:1
    },
    {
      pos:[
        4,
        1,
        10
      ],
      state:1
    },
    {
      pos:[
        4,
        1,
        11
      ],
      state:1
    },
    {
      pos:[
        4,
        1,
        12
      ],
      state:1
    },
    {
      pos:[
        4,
        1,
        13
      ],
      state:1
    },
    {
      pos:[
        4,
        1,
        14
      ],
      state:1
    },
    {
      pos:[
        4,
        1,
        15
      ],
      state:1
    },
    {
      pos:[
        4,
        1,
        16
      ],
      state:1
    },
    {
      pos:[
        4,
        1,
        17
      ],
      state:1
    },
    {
      pos:[
        4,
        1,
        18
      ],
      state:1
    },
    {
      pos:[
        4,
        1,
        19
      ],
      state:1
    },
    {
      pos:[
        5,
        1,
        0
      ],
      state:1
    },
    {
      pos:[
        5,
        1,
        1
      ],
      state:1
    },
    {
      pos:[
        5,
        1,
        2
      ],
      state:1
    },
    {
      pos:[
        5,
        1,
        3
      ],
      state:1
    },
    {
      pos:[
        5,
        1,
        4
      ],
      state:1
    },
    {
      pos:[
        5,
        1,
        5
      ],
      state:1
    },
    {
      pos:[
        5,
        1,
        6
      ],
      state:1
    },
    {
      pos:[
        5,
        1,
        7
      ],
      state:1
    },
    {
      pos:[
        5,
        1,
        8
      ],
      state:1
    },
    {
      pos:[
        5,
        1,
        9
      ],
      state:1
    },
    {
      pos:[
        5,
        1,
        10
      ],
      state:1
    },
    {
      pos:[
        5,
        1,
        11
      ],
      state:1
    },
    {
      pos:[
        5,
        1,
        12
      ],
      state:1
    },
    {
      pos:[
        5,
        1,
        13
      ],
      state:1
    },
    {
      pos:[
        5,
        1,
        14
      ],
      state:1
    },
    {
      pos:[
        5,
        1,
        15
      ],
      state:1
    },
    {
      pos:[
        5,
        1,
        16
      ],
      state:1
    },
    {
      pos:[
        5,
        1,
        17
      ],
      state:1
    },
    {
      pos:[
        5,
        1,
        18
      ],
      state:1
    },
    {
      pos:[
        5,
        1,
        19
      ],
      state:1
    },
    {
      pos:[
        6,
        1,
        0
      ],
      state:1
    },
    {
      pos:[
        6,
        1,
        1
      ],
      state:1
    },
    {
      pos:[
        6,
        1,
        2
      ],
      state:1
    },
    {
      pos:[
        6,
        1,
        3
      ],
      state:1
    },
    {
      pos:[
        6,
        1,
        4
      ],
      state:1
    },
    {
      pos:[
        6,
        1,
        5
      ],
      state:1
    },
    {
      pos:[
        6,
        1,
        6
      ],
      state:1
    },
    {
      pos:[
        6,
        1,
        7
      ],
      state:1
    },
    {
      pos:[
        6,
        1,
        8
      ],
      state:1
    },
    {
      pos:[
        6,
        1,
        9
      ],
      state:1
    },
    {
      pos:[
        6,
        1,
        10
      ],
      state:1
    },
    {
      pos:[
        6,
        1,
        11
      ],
      state:1
    },
    {
      pos:[
        6,
        1,
        12
      ],
      state:1
    },
    {
      pos:[
        6,
        1,
        13
      ],
      state:1
    },
    {
      pos:[
        6,
        1,
        14
      ],
      state:1
    },
    {
      pos:[
        6,
        1,
        15
      ],
      state:1
    },
    {
      pos:[
        6,
        1,
        16
      ],
      state:1
    },
    {
      pos:[
        6,
        1,
        17
      ],
      state:1
    },
    {
      pos:[
        6,
        1,
        18
      ],
      state:1
    },
    {
      pos:[
        6,
        1,
        19
      ],
      state:1
    },
    {
      pos:[
        7,
        1,
        0
      ],
      state:1
    },
    {
      pos:[
        7,
        1,
        1
      ],
      state:1
    },
    {
      pos:[
        7,
        1,
        2
      ],
      state:1
    },
    {
      pos:[
        7,
        1,
        3
      ],
      state:1
    },
    {
      pos:[
        7,
        1,
        4
      ],
      state:1
    },
    {
      pos:[
        7,
        1,
        5
      ],
      state:1
    },
    {
      pos:[
        7,
        1,
        6
      ],
      state:1
    },
    {
      pos:[
        7,
        1,
        7
      ],
      state:1
    },
    {
      pos:[
        7,
        1,
        8
      ],
      state:1
    },
    {
      pos:[
        7,
        1,
        9
      ],
      state:1
    },
    {
      pos:[
        7,
        1,
        10
      ],
      state:1
    },
    {
      pos:[
        7,
        1,
        11
      ],
      state:1
    },
    {
      pos:[
        7,
        1,
        12
      ],
      state:1
    },
    {
      pos:[
        7,
        1,
        13
      ],
      state:1
    },
    {
      pos:[
        7,
        1,
        14
      ],
      state:1
    },
    {
      pos:[
        7,
        1,
        15
      ],
      state:1
    },
    {
      pos:[
        7,
        1,
        16
      ],
      state:1
    },
    {
      pos:[
        7,
        1,
        17
      ],
      state:1
    },
    {
      pos:[
        7,
        1,
        18
      ],
      state:1
    },
    {
      pos:[
        7,
        1,
        19
      ],
      state:1
    },
    {
      pos:[
        8,
        1,
        0
      ],
      state:1
    },
    {
      pos:[
        8,
        1,
        1
      ],
      state:1
    },
    {
      pos:[
        8,
        1,
        2
      ],
      state:1
    },
    {
      pos:[
        8,
        1,
        3
      ],
      state:1
    },
    {
      pos:[
        8,
        1,
        4
      ],
      state:1
    },
    {
      pos:[
        8,
        1,
        5
      ],
      state:1
    },
    {
      pos:[
        8,
        1,
        6
      ],
      state:1
    },
    {
      pos:[
        8,
        1,
        7
      ],
      state:1
    },
    {
      pos:[
        8,
        1,
        8
      ],
      state:1
    },
    {
      pos:[
        8,
        1,
        9
      ],
      state:1
    },
    {
      pos:[
        8,
        1,
        10
      ],
      state:1
    },
    {
      pos:[
        8,
        1,
        11
      ],
      state:1
    },
    {
      pos:[
        8,
        1,
        12
      ],
      state:1
    },
    {
      pos:[
        8,
        1,
        13
      ],
      state:1
    },
    {
      pos:[
        8,
        1,
        14
      ],
      state:1
    },
    {
      pos:[
        8,
        1,
        15
      ],
      state:1
    },
    {
      pos:[
        8,
        1,
        16
      ],
      state:1
    },
    {
      pos:[
        8,
        1,
        17
      ],
      state:1
    },
    {
      pos:[
        8,
        1,
        18
      ],
      state:1
    },
    {
      pos:[
        8,
        1,
        19
      ],
      state:1
    },
    {
      pos:[
        9,
        1,
        0
      ],
      state:1
    },
    {
      pos:[
        9,
        1,
        1
      ],
      state:1
    },
    {
      pos:[
        9,
        1,
        2
      ],
      state:1
    },
    {
      pos:[
        9,
        1,
        3
      ],
      state:1
    },
    {
      pos:[
        9,
        1,
        4
      ],
      state:1
    },
    {
      pos:[
        9,
        1,
        5
      ],
      state:1
    },
    {
      pos:[
        9,
        1,
        6
      ],
      state:1
    },
    {
      pos:[
        9,
        1,
        7
      ],
      state:1
    },
    {
      pos:[
        9,
        1,
        8
      ],
      state:1
    },
    {
      pos:[
        9,
        1,
        11
      ],
      state:1
    },
    {
      pos:[
        9,
        1,
        12
      ],
      state:1
    },
    {
      pos:[
        9,
        1,
        13
      ],
      state:1
    },
    {
      pos:[
        9,
        1,
        14
      ],
      state:1
    },
    {
      pos:[
        9,
        1,
        15
      ],
      state:1
    },
    {
      pos:[
        9,
        1,
        16
      ],
      state:1
    },
    {
      pos:[
        9,
        1,
        17
      ],
      state:1
    },
    {
      pos:[
        9,
        1,
        18
      ],
      state:1
    },
    {
      pos:[
        9,
        1,
        19
      ],
      state:1
    },
    {
      pos:[
        10,
        1,
        0
      ],
      state:1
    },
    {
      pos:[
        10,
        1,
        1
      ],
      state:1
    },
    {
      pos:[
        10,
        1,
        2
      ],
      state:1
    },
    {
      pos:[
        10,
        1,
        3
      ],
      state:1
    },
    {
      pos:[
        10,
        1,
        4
      ],
      state:1
    },
    {
      pos:[
        10,
        1,
        5
      ],
      state:1
    },
    {
      pos:[
        10,
        1,
        6
      ],
      state:1
    },
    {
      pos:[
        10,
        1,
        7
      ],
      state:1
    },
    {
      pos:[
        10,
        1,
        8
      ],
      state:1
    },
    {
      pos:[
        10,
        1,
        11
      ],
      state:1
    },
    {
      pos:[
        10,
        1,
        12
      ],
      state:1
    },
    {
      pos:[
        10,
        1,
        13
      ],
      state:1
    },
    {
      pos:[
        10,
        1,
        14
      ],
      state:1
    },
    {
      pos:[
        10,
        1,
        15
      ],
      state:1
    },
    {
      pos:[
        10,
        1,
        16
      ],
      state:1
    },
    {
      pos:[
        10,
        1,
        17
      ],
      state:1
    },
    {
      pos:[
        10,
        1,
        18
      ],
      state:1
    },
    {
      pos:[
        10,
        1,
        19
      ],
      state:1
    },
    {
      pos:[
        11,
        1,
        0
      ],
      state:1
    },
    {
      pos:[
        11,
        1,
        1
      ],
      state:1
    },
    {
      pos:[
        11,
        1,
        2
      ],
      state:1
    },
    {
      pos:[
        11,
        1,
        3
      ],
      state:1
    },
    {
      pos:[
        11,
        1,
        4
      ],
      state:1
    },
    {
      pos:[
        11,
        1,
        5
      ],
      state:1
    },
    {
      pos:[
        11,
        1,
        6
      ],
      state:1
    },
    {
      pos:[
        11,
        1,
        7
      ],
      state:1
    },
    {
      pos:[
        11,
        1,
        8
      ],
      state:1
    },
    {
      pos:[
        11,
        1,
        9
      ],
      state:1
    },
    {
      pos:[
        11,
        1,
        10
      ],
      state:1
    },
    {
      pos:[
        11,
        1,
        11
      ],
      state:1
    },
    {
      pos:[
        11,
        1,
        12
      ],
      state:1
    },
    {
      pos:[
        11,
        1,
        13
      ],
      state:1
    },
    {
      pos:[
        11,
        1,
        14
      ],
      state:1
    },
    {
      pos:[
        11,
        1,
        15
      ],
      state:1
    },
    {
      pos:[
        11,
        1,
        16
      ],
      state:1
    },
    {
      pos:[
        11,
        1,
        17
      ],
      state:1
    },
    {
      pos:[
        11,
        1,
        18
      ],
      state:1
    },
    {
      pos:[
        11,
        1,
        19
      ],
      state:1
    },
    {
      pos:[
        12,
        1,
        0
      ],
      state:1
    },
    {
      pos:[
        12,
        1,
        1
      ],
      state:1
    },
    {
      pos:[
        12,
        1,
        2
      ],
      state:1
    },
    {
      pos:[
        12,
        1,
        3
      ],
      state:1
    },
    {
      pos:[
        12,
        1,
        4
      ],
      state:1
    },
    {
      pos:[
        12,
        1,
        5
      ],
      state:1
    },
    {
      pos:[
        12,
        1,
        6
      ],
      state:1
    },
    {
      pos:[
        12,
        1,
        7
      ],
      state:1
    },
    {
      pos:[
        12,
        1,
        8
      ],
      state:1
    },
    {
      pos:[
        12,
        1,
        9
      ],
      state:1
    },
    {
      pos:[
        12,
        1,
        10
      ],
      state:1
    },
    {
      pos:[
        12,
        1,
        11
      ],
      state:1
    },
    {
      pos:[
        12,
        1,
        12
      ],
      state:1
    },
    {
      pos:[
        12,
        1,
        13
      ],
      state:1
    },
    {
      pos:[
        12,
        1,
        14
      ],
      state:1
    },
    {
      pos:[
        12,
        1,
        15
      ],
      state:1
    },
    {
      pos:[
        12,
        1,
        16
      ],
      state:1
    },
    {
      pos:[
        12,
        1,
        17
      ],
      state:1
    },
    {
      pos:[
        12,
        1,
        18
      ],
      state:1
    },
    {
      pos:[
        12,
        1,
        19
      ],
      state:1
    },
    {
      pos:[
        0,
        2,
        1
      ],
      state:2
    },
    {
      pos:[
        0,
        2,
        2
      ],
      state:3
    },
    {
      pos:[
        0,
        2,
        3
      ],
      state:2
    },
    {
      pos:[
        0,
        2,
        4
      ],
      state:3
    },
    {
      pos:[
        0,
        2,
        5
      ],
      state:2
    },
    {
      pos:[
        0,
        2,
        6
      ],
      state:3
    },
    {
      pos:[
        0,
        2,
        7
      ],
      state:2
    },
    {
      pos:[
        0,
        2,
        8
      ],
      state:3
    },
    {
      pos:[
        0,
        2,
        9
      ],
      state:2
    },
    {
      pos:[
        0,
        2,
        10
      ],
      state:3
    },
    {
      pos:[
        0,
        2,
        11
      ],
      state:2
    },
    {
      pos:[
        0,
        2,
        12
      ],
      state:3
    },
    {
      pos:[
        0,
        2,
        13
      ],
      state:2
    },
    {
      pos:[
        0,
        2,
        14
      ],
      state:3
    },
    {
      pos:[
        0,
        2,
        15
      ],
      state:2
    },
    {
      pos:[
        0,
        2,
        16
      ],
      state:3
    },
    {
      pos:[
        0,
        2,
        17
      ],
      state:2
    },
    {
      pos:[
        0,
        2,
        18
      ],
      state:3
    },
    {
      pos:[
        0,
        2,
        19
      ],
      state:2
    },
    {
      pos:[
        1,
        2,
        0
      ],
      state:3
    },
    {
      pos:[
        1,
        2,
        1
      ],
      state:3
    },
    {
      pos:[
        1,
        2,
        14
      ],
      state:4
    },
    {
      pos:[
        1,
        2,
        15
      ],
      state:4
    },
    {
      pos:[
        1,
        2,
        16
      ],
      state:4
    },
    {
      pos:[
        1,
        2,
        17
      ],
      state:4
    },
    {
      pos:[
        1,
        2,
        18
      ],
      state:4
    },
    {
      pos:[
        1,
        2,
        19
      ],
      state:3
    },
    {
      pos:[
        2,
        2,
        0
      ],
      state:2
    },
    {
      pos:[
        2,
        2,
        1
      ],
      state:5
    },
    {
      pos:[
        2,
        2,
        14
      ],
      state:4
    },
    {
      pos:[
        2,
        2,
        18
      ],
      state:4
    },
    {
      pos:[
        2,
        2,
        19
      ],
      state:2
    },
    {
      pos:[
        3,
        2,
        0
      ],
      state:3
    },
    {
      pos:[
        3,
        2,
        1
      ],
      state:5
    },
    {
      pos:[
        3,
        2,
        19
      ],
      state:3
    },
    {
      pos:[
        4,
        2,
        0
      ],
      state:2
    },
    {
      pos:[
        4,
        2,
        1
      ],
      state:5
    },
    {
      pos:[
        4,
        2,
        19
      ],
      state:2
    },
    {
      pos:[
        5,
        2,
        0
      ],
      state:3
    },
    {
      pos:[
        5,
        2,
        1
      ],
      state:5
    },
    {
      pos:[
        5,
        2,
        6
      ],
      state:6
    },
    {
      pos:[
        5,
        2,
        19
      ],
      state:3
    },
    {
      pos:[
        6,
        2,
        0
      ],
      state:2
    },
    {
      pos:[
        6,
        2,
        19
      ],
      state:2
    },
    {
      pos:[
        7,
        2,
        0
      ],
      state:3
    },
    {
      pos:[
        7,
        2,
        13
      ],
      state:3
    },
    {
      pos:[
        7,
        2,
        19
      ],
      state:3
    },
    {
      pos:[
        8,
        2,
        0
      ],
      state:2
    },
    {
      pos:[
        8,
        2,
        13
      ],
      state:2
    },
    {
      pos:[
        8,
        2,
        19
      ],
      state:2
    },
    {
      pos:[
        9,
        2,
        0
      ],
      state:3
    },
    {
      pos:[
        9,
        2,
        13
      ],
      state:3
    },
    {
      pos:[
        9,
        2,
        19
      ],
      state:3
    },
    {
      pos:[
        10,
        2,
        0
      ],
      state:2
    },
    {
      pos:[
        10,
        2,
        13
      ],
      state:2
    },
    {
      pos:[
        10,
        2,
        19
      ],
      state:2
    },
    {
      pos:[
        11,
        2,
        0
      ],
      state:3
    },
    {
      pos:[
        11,
        2,
        13
      ],
      state:3
    },
    {
      pos:[
        11,
        2,
        19
      ],
      state:3
    },
    {
      pos:[
        12,
        2,
        0
      ],
      state:2
    },
    {
      pos:[
        12,
        2,
        1
      ],
      state:2
    },
    {
      pos:[
        12,
        2,
        2
      ],
      state:3
    },
    {
      pos:[
        12,
        2,
        3
      ],
      state:2
    },
    {
      pos:[
        12,
        2,
        4
      ],
      state:3
    },
    {
      pos:[
        12,
        2,
        5
      ],
      state:2
    },
    {
      pos:[
        12,
        2,
        6
      ],
      state:3
    },
    {
      pos:[
        12,
        2,
        7
      ],
      state:2
    },
    {
      pos:[
        12,
        2,
        8
      ],
      state:3
    },
    {
      pos:[
        12,
        2,
        9
      ],
      state:2
    },
    {
      pos:[
        12,
        2,
        10
      ],
      state:3
    },
    {
      pos:[
        12,
        2,
        11
      ],
      state:2
    },
    {
      pos:[
        12,
        2,
        12
      ],
      state:3
    },
    {
      pos:[
        12,
        2,
        13
      ],
      state:2
    },
    {
      pos:[
        12,
        2,
        14
      ],
      state:3
    },
    {
      pos:[
        12,
        2,
        15
      ],
      state:2
    },
    {
      pos:[
        12,
        2,
        16
      ],
      state:3
    },
    {
      pos:[
        12,
        2,
        17
      ],
      state:2
    },
    {
      pos:[
        12,
        2,
        18
      ],
      state:3
    },
    {
      pos:[
        12,
        2,
        19
      ],
      state:2
    },
    {
      pos:[
        0,
        3,
        1
      ],
      state:7
    },
    {
      pos:[
        0,
        3,
        2
      ],
      state:7
    },
    {
      pos:[
        0,
        3,
        3
      ],
      state:7
    },
    {
      pos:[
        0,
        3,
        4
      ],
      state:7
    },
    {
      pos:[
        0,
        3,
        5
      ],
      state:7
    },
    {
      pos:[
        0,
        3,
        6
      ],
      state:7
    },
    {
      pos:[
        0,
        3,
        7
      ],
      state:7
    },
    {
      pos:[
        0,
        3,
        8
      ],
      state:7
    },
    {
      pos:[
        0,
        3,
        9
      ],
      state:7
    },
    {
      pos:[
        0,
        3,
        10
      ],
      state:7
    },
    {
      pos:[
        0,
        3,
        11
      ],
      state:7
    },
    {
      pos:[
        0,
        3,
        12
      ],
      state:7
    },
    {
      pos:[
        0,
        3,
        13
      ],
      state:7
    },
    {
      pos:[
        0,
        3,
        14
      ],
      state:7
    },
    {
      pos:[
        0,
        3,
        15
      ],
      state:7
    },
    {
      pos:[
        0,
        3,
        16
      ],
      state:7
    },
    {
      pos:[
        0,
        3,
        17
      ],
      state:7
    },
    {
      pos:[
        0,
        3,
        18
      ],
      state:7
    },
    {
      pos:[
        0,
        3,
        19
      ],
      state:7
    },
    {
      pos:[
        1,
        3,
        0
      ],
      state:7
    },
    {
      pos:[
        1,
        3,
        1
      ],
      state:7
    },
    {
      pos:[
        1,
        3,
        19
      ],
      state:7
    },
    {
      pos:[
        2,
        3,
        0
      ],
      state:7
    },
    {
      pos:[
        2,
        3,
        1
      ],
      state:5
    },
    {
      pos:[
        2,
        3,
        19
      ],
      state:7
    },
    {
      pos:[
        3,
        3,
        0
      ],
      state:7
    },
    {
      pos:[
        3,
        3,
        1
      ],
      state:5
    },
    {
      pos:[
        3,
        3,
        19
      ],
      state:7
    },
    {
      pos:[
        4,
        3,
        0
      ],
      state:7
    },
    {
      pos:[
        4,
        3,
        1
      ],
      state:5
    },
    {
      pos:[
        4,
        3,
        19
      ],
      state:7
    },
    {
      pos:[
        5,
        3,
        0
      ],
      state:7
    },
    {
      pos:[
        5,
        3,
        1
      ],
      state:5
    },
    {
      pos:[
        5,
        3,
        19
      ],
      state:7
    },
    {
      pos:[
        6,
        3,
        0
      ],
      state:7
    },
    {
      pos:[
        6,
        3,
        19
      ],
      state:7
    },
    {
      pos:[
        7,
        3,
        0
      ],
      state:7
    },
    {
      pos:[
        7,
        3,
        13
      ],
      state:7
    },
    {
      pos:[
        7,
        3,
        19
      ],
      state:7
    },
    {
      pos:[
        8,
        3,
        0
      ],
      state:7
    },
    {
      pos:[
        8,
        3,
        13
      ],
      state:7
    },
    {
      pos:[
        8,
        3,
        19
      ],
      state:7
    },
    {
      pos:[
        9,
        3,
        0
      ],
      state:7
    },
    {
      pos:[
        9,
        3,
        13
      ],
      state:7
    },
    {
      pos:[
        9,
        3,
        19
      ],
      state:7
    },
    {
      pos:[
        10,
        3,
        0
      ],
      state:7
    },
    {
      pos:[
        10,
        3,
        13
      ],
      state:7
    },
    {
      pos:[
        10,
        3,
        19
      ],
      state:7
    },
    {
      pos:[
        11,
        3,
        0
      ],
      state:7
    },
    {
      pos:[
        11,
        3,
        13
      ],
      state:7
    },
    {
      pos:[
        11,
        3,
        15
      ],
      state:8
    },
    {
      pos:[
        11,
        3,
        16
      ],
      state:8
    },
    {
      pos:[
        11,
        3,
        17
      ],
      state:8
    },
    {
      pos:[
        11,
        3,
        19
      ],
      state:7
    },
    {
      pos:[
        12,
        3,
        0
      ],
      state:7
    },
    {
      pos:[
        12,
        3,
        1
      ],
      state:7
    },
    {
      pos:[
        12,
        3,
        2
      ],
      state:7
    },
    {
      pos:[
        12,
        3,
        3
      ],
      state:7
    },
    {
      pos:[
        12,
        3,
        4
      ],
      state:7
    },
    {
      pos:[
        12,
        3,
        5
      ],
      state:7
    },
    {
      pos:[
        12,
        3,
        6
      ],
      state:7
    },
    {
      pos:[
        12,
        3,
        7
      ],
      state:7
    },
    {
      pos:[
        12,
        3,
        8
      ],
      state:7
    },
    {
      pos:[
        12,
        3,
        9
      ],
      state:7
    },
    {
      pos:[
        12,
        3,
        10
      ],
      state:7
    },
    {
      pos:[
        12,
        3,
        11
      ],
      state:7
    },
    {
      pos:[
        12,
        3,
        12
      ],
      state:7
    },
    {
      pos:[
        12,
        3,
        13
      ],
      state:7
    },
    {
      pos:[
        12,
        3,
        14
      ],
      state:7
    },
    {
      pos:[
        12,
        3,
        15
      ],
      state:7
    },
    {
      pos:[
        12,
        3,
        16
      ],
      state:7
    },
    {
      pos:[
        12,
        3,
        17
      ],
      state:7
    },
    {
      pos:[
        12,
        3,
        18
      ],
      state:7
    },
    {
      pos:[
        12,
        3,
        19
      ],
      state:7
    },
    {
      pos:[
        0,
        4,
        1
      ],
      state:7
    },
    {
      pos:[
        0,
        4,
        2
      ],
      state:7
    },
    {
      pos:[
        0,
        4,
        3
      ],
      state:7
    },
    {
      pos:[
        0,
        4,
        4
      ],
      state:7
    },
    {
      pos:[
        0,
        4,
        5
      ],
      state:7
    },
    {
      pos:[
        0,
        4,
        6
      ],
      state:7
    },
    {
      pos:[
        0,
        4,
        7
      ],
      state:7
    },
    {
      pos:[
        0,
        4,
        8
      ],
      state:7
    },
    {
      pos:[
        0,
        4,
        9
      ],
      state:7
    },
    {
      pos:[
        0,
        4,
        10
      ],
      state:7
    },
    {
      pos:[
        0,
        4,
        11
      ],
      state:7
    },
    {
      pos:[
        0,
        4,
        12
      ],
      state:7
    },
    {
      pos:[
        0,
        4,
        13
      ],
      state:7
    },
    {
      pos:[
        0,
        4,
        14
      ],
      state:7
    },
    {
      pos:[
        0,
        4,
        15
      ],
      state:7
    },
    {
      pos:[
        0,
        4,
        16
      ],
      state:7
    },
    {
      pos:[
        0,
        4,
        17
      ],
      state:7
    },
    {
      pos:[
        0,
        4,
        18
      ],
      state:7
    },
    {
      pos:[
        0,
        4,
        19
      ],
      state:7
    },
    {
      pos:[
        1,
        4,
        0
      ],
      state:7
    },
    {
      pos:[
        1,
        4,
        1
      ],
      state:7
    },
    {
      pos:[
        1,
        4,
        19
      ],
      state:7
    },
    {
      pos:[
        2,
        4,
        0
      ],
      state:7
    },
    {
      pos:[
        2,
        4,
        1
      ],
      state:5
    },
    {
      pos:[
        2,
        4,
        19
      ],
      state:7
    },
    {
      pos:[
        3,
        4,
        0
      ],
      state:7
    },
    {
      pos:[
        3,
        4,
        1
      ],
      state:5
    },
    {
      pos:[
        3,
        4,
        19
      ],
      state:7
    },
    {
      pos:[
        4,
        4,
        0
      ],
      state:7
    },
    {
      pos:[
        4,
        4,
        1
      ],
      state:5
    },
    {
      pos:[
        4,
        4,
        19
      ],
      state:7
    },
    {
      pos:[
        5,
        4,
        0
      ],
      state:7
    },
    {
      pos:[
        5,
        4,
        1
      ],
      state:5
    },
    {
      pos:[
        5,
        4,
        19
      ],
      state:7
    },
    {
      pos:[
        6,
        4,
        0
      ],
      state:7
    },
    {
      pos:[
        6,
        4,
        19
      ],
      state:7
    },
    {
      pos:[
        7,
        4,
        0
      ],
      state:7
    },
    {
      pos:[
        7,
        4,
        13
      ],
      state:7
    },
    {
      pos:[
        7,
        4,
        19
      ],
      state:7
    },
    {
      pos:[
        8,
        4,
        0
      ],
      state:7
    },
    {
      pos:[
        8,
        4,
        13
      ],
      state:7
    },
    {
      pos:[
        8,
        4,
        19
      ],
      state:7
    },
    {
      pos:[
        9,
        4,
        0
      ],
      state:7
    },
    {
      pos:[
        9,
        4,
        13
      ],
      state:7
    },
    {
      pos:[
        9,
        4,
        19
      ],
      state:7
    },
    {
      pos:[
        10,
        4,
        0
      ],
      state:7
    },
    {
      pos:[
        10,
        4,
        13
      ],
      state:7
    },
    {
      pos:[
        10,
        4,
        19
      ],
      state:7
    },
    {
      pos:[
        11,
        4,
        0
      ],
      state:7
    },
    {
      pos:[
        11,
        4,
        13
      ],
      state:7
    },
    {
      pos:[
        11,
        4,
        15
      ],
      state:8
    },
    {
      pos:[
        11,
        4,
        16
      ],
      state:8
    },
    {
      pos:[
        11,
        4,
        17
      ],
      state:8
    },
    {
      pos:[
        11,
        4,
        19
      ],
      state:7
    },
    {
      pos:[
        12,
        4,
        0
      ],
      state:7
    },
    {
      pos:[
        12,
        4,
        1
      ],
      state:7
    },
    {
      pos:[
        12,
        4,
        2
      ],
      state:7
    },
    {
      pos:[
        12,
        4,
        3
      ],
      state:7
    },
    {
      pos:[
        12,
        4,
        4
      ],
      state:7
    },
    {
      pos:[
        12,
        4,
        5
      ],
      state:7
    },
    {
      pos:[
        12,
        4,
        6
      ],
      state:7
    },
    {
      pos:[
        12,
        4,
        7
      ],
      state:7
    },
    {
      pos:[
        12,
        4,
        8
      ],
      state:7
    },
    {
      pos:[
        12,
        4,
        9
      ],
      state:7
    },
    {
      pos:[
        12,
        4,
        10
      ],
      state:7
    },
    {
      pos:[
        12,
        4,
        11
      ],
      state:7
    },
    {
      pos:[
        12,
        4,
        12
      ],
      state:7
    },
    {
      pos:[
        12,
        4,
        13
      ],
      state:7
    },
    {
      pos:[
        12,
        4,
        14
      ],
      state:7
    },
    {
      pos:[
        12,
        4,
        15
      ],
      state:7
    },
    {
      pos:[
        12,
        4,
        16
      ],
      state:7
    },
    {
      pos:[
        12,
        4,
        17
      ],
      state:7
    },
    {
      pos:[
        12,
        4,
        18
      ],
      state:7
    },
    {
      pos:[
        12,
        4,
        19
      ],
      state:7
    },
    {
      pos:[
        0,
        5,
        1
      ],
      state:7
    },
    {
      pos:[
        0,
        5,
        2
      ],
      state:7
    },
    {
      pos:[
        0,
        5,
        3
      ],
      state:7
    },
    {
      pos:[
        0,
        5,
        4
      ],
      state:7
    },
    {
      pos:[
        0,
        5,
        5
      ],
      state:7
    },
    {
      pos:[
        0,
        5,
        6
      ],
      state:7
    },
    {
      pos:[
        0,
        5,
        7
      ],
      state:7
    },
    {
      pos:[
        0,
        5,
        8
      ],
      state:7
    },
    {
      pos:[
        0,
        5,
        9
      ],
      state:7
    },
    {
      pos:[
        0,
        5,
        10
      ],
      state:7
    },
    {
      pos:[
        0,
        5,
        11
      ],
      state:7
    },
    {
      pos:[
        0,
        5,
        12
      ],
      state:7
    },
    {
      pos:[
        0,
        5,
        13
      ],
      state:7
    },
    {
      pos:[
        0,
        5,
        14
      ],
      state:7
    },
    {
      pos:[
        0,
        5,
        15
      ],
      state:7
    },
    {
      pos:[
        0,
        5,
        16
      ],
      state:7
    },
    {
      pos:[
        0,
        5,
        17
      ],
      state:7
    },
    {
      pos:[
        0,
        5,
        18
      ],
      state:7
    },
    {
      pos:[
        0,
        5,
        19
      ],
      state:7
    },
    {
      pos:[
        1,
        5,
        0
      ],
      state:7
    },
    {
      pos:[
        1,
        5,
        1
      ],
      state:7
    },
    {
      pos:[
        1,
        5,
        19
      ],
      state:7
    },
    {
      pos:[
        2,
        5,
        0
      ],
      state:7
    },
    {
      pos:[
        2,
        5,
        19
      ],
      state:7
    },
    {
      pos:[
        3,
        5,
        0
      ],
      state:7
    },
    {
      pos:[
        3,
        5,
        19
      ],
      state:7
    },
    {
      pos:[
        4,
        5,
        0
      ],
      state:7
    },
    {
      pos:[
        4,
        5,
        19
      ],
      state:7
    },
    {
      pos:[
        5,
        5,
        0
      ],
      state:7
    },
    {
      pos:[
        5,
        5,
        19
      ],
      state:7
    },
    {
      pos:[
        6,
        5,
        0
      ],
      state:7
    },
    {
      pos:[
        6,
        5,
        19
      ],
      state:7
    },
    {
      pos:[
        7,
        5,
        0
      ],
      state:7
    },
    {
      pos:[
        7,
        5,
        13
      ],
      state:7
    },
    {
      pos:[
        7,
        5,
        19
      ],
      state:7
    },
    {
      pos:[
        8,
        5,
        0
      ],
      state:7
    },
    {
      pos:[
        8,
        5,
        13
      ],
      state:7
    },
    {
      pos:[
        8,
        5,
        19
      ],
      state:7
    },
    {
      pos:[
        9,
        5,
        0
      ],
      state:7
    },
    {
      pos:[
        9,
        5,
        13
      ],
      state:7
    },
    {
      pos:[
        9,
        5,
        19
      ],
      state:7
    },
    {
      pos:[
        10,
        5,
        0
      ],
      state:7
    },
    {
      pos:[
        10,
        5,
        13
      ],
      state:7
    },
    {
      pos:[
        10,
        5,
        19
      ],
      state:7
    },
    {
      pos:[
        11,
        5,
        0
      ],
      state:7
    },
    {
      pos:[
        11,
        5,
        13
      ],
      state:7
    },
    {
      pos:[
        11,
        5,
        19
      ],
      state:7
    },
    {
      pos:[
        12,
        5,
        0
      ],
      state:7
    },
    {
      pos:[
        12,
        5,
        1
      ],
      state:7
    },
    {
      pos:[
        12,
        5,
        2
      ],
      state:7
    },
    {
      pos:[
        12,
        5,
        3
      ],
      state:7
    },
    {
      pos:[
        12,
        5,
        4
      ],
      state:7
    },
    {
      pos:[
        12,
        5,
        5
      ],
      state:7
    },
    {
      pos:[
        12,
        5,
        6
      ],
      state:7
    },
    {
      pos:[
        12,
        5,
        7
      ],
      state:7
    },
    {
      pos:[
        12,
        5,
        8
      ],
      state:7
    },
    {
      pos:[
        12,
        5,
        9
      ],
      state:7
    },
    {
      pos:[
        12,
        5,
        10
      ],
      state:7
    },
    {
      pos:[
        12,
        5,
        11
      ],
      state:7
    },
    {
      pos:[
        12,
        5,
        12
      ],
      state:7
    },
    {
      pos:[
        12,
        5,
        13
      ],
      state:7
    },
    {
      pos:[
        12,
        5,
        14
      ],
      state:7
    },
    {
      pos:[
        12,
        5,
        15
      ],
      state:7
    },
    {
      pos:[
        12,
        5,
        16
      ],
      state:7
    },
    {
      pos:[
        12,
        5,
        17
      ],
      state:7
    },
    {
      pos:[
        12,
        5,
        18
      ],
      state:7
    },
    {
      pos:[
        12,
        5,
        19
      ],
      state:7
    },
    {
      pos:[
        0,
        0,
        0
      ],
      state:9
    },
    {
      pos:[
        0,
        0,
        1
      ],
      state:9
    },
    {
      pos:[
        0,
        0,
        2
      ],
      state:9
    },
    {
      pos:[
        0,
        0,
        3
      ],
      state:9
    },
    {
      pos:[
        0,
        0,
        4
      ],
      state:9
    },
    {
      pos:[
        0,
        0,
        5
      ],
      state:9
    },
    {
      pos:[
        0,
        0,
        6
      ],
      state:9
    },
    {
      pos:[
        0,
        0,
        7
      ],
      state:9
    },
    {
      pos:[
        0,
        0,
        8
      ],
      state:9
    },
    {
      pos:[
        0,
        0,
        9
      ],
      state:9
    },
    {
      pos:[
        0,
        0,
        10
      ],
      state:9
    },
    {
      pos:[
        0,
        0,
        11
      ],
      state:9
    },
    {
      pos:[
        0,
        0,
        12
      ],
      state:9
    },
    {
      pos:[
        0,
        0,
        13
      ],
      state:9
    },
    {
      pos:[
        0,
        0,
        14
      ],
      state:9
    },
    {
      pos:[
        0,
        0,
        15
      ],
      state:9
    },
    {
      pos:[
        0,
        0,
        16
      ],
      state:9
    },
    {
      pos:[
        0,
        0,
        17
      ],
      state:9
    },
    {
      pos:[
        0,
        0,
        18
      ],
      state:9
    },
    {
      pos:[
        0,
        0,
        19
      ],
      state:9
    },
    {
      pos:[
        1,
        0,
        0
      ],
      state:9
    },
    {
      pos:[
        1,
        0,
        1
      ],
      state:9
    },
    {
      pos:[
        1,
        0,
        2
      ],
      state:9
    },
    {
      pos:[
        1,
        0,
        3
      ],
      state:9
    },
    {
      pos:[
        1,
        0,
        4
      ],
      state:9
    },
    {
      pos:[
        1,
        0,
        5
      ],
      state:9
    },
    {
      pos:[
        1,
        0,
        6
      ],
      state:9
    },
    {
      pos:[
        1,
        0,
        7
      ],
      state:9
    },
    {
      pos:[
        1,
        0,
        8
      ],
      state:9
    },
    {
      pos:[
        1,
        0,
        9
      ],
      state:9
    },
    {
      pos:[
        1,
        0,
        10
      ],
      state:9
    },
    {
      pos:[
        1,
        0,
        11
      ],
      state:9
    },
    {
      pos:[
        1,
        0,
        12
      ],
      state:9
    },
    {
      pos:[
        1,
        0,
        13
      ],
      state:9
    },
    {
      pos:[
        1,
        0,
        14
      ],
      state:9
    },
    {
      pos:[
        1,
        0,
        15
      ],
      state:9
    },
    {
      pos:[
        1,
        0,
        16
      ],
      state:9
    },
    {
      pos:[
        1,
        0,
        17
      ],
      state:9
    },
    {
      pos:[
        1,
        0,
        19
      ],
      state:10
    },
    {
      pos:[
        2,
        0,
        0
      ],
      state:9
    },
    {
      pos:[
        2,
        0,
        1
      ],
      state:9
    },
    {
      pos:[
        2,
        0,
        2
      ],
      state:9
    },
    {
      pos:[
        2,
        0,
        3
      ],
      state:9
    },
    {
      pos:[
        2,
        0,
        4
      ],
      state:9
    },
    {
      pos:[
        2,
        0,
        5
      ],
      state:9
    },
    {
      pos:[
        2,
        0,
        6
      ],
      state:9
    },
    {
      pos:[
        2,
        0,
        7
      ],
      state:9
    },
    {
      pos:[
        2,
        0,
        8
      ],
      state:9
    },
    {
      pos:[
        2,
        0,
        9
      ],
      state:9
    },
    {
      pos:[
        2,
        0,
        10
      ],
      state:9
    },
    {
      pos:[
        2,
        0,
        11
      ],
      state:9
    },
    {
      pos:[
        2,
        0,
        12
      ],
      state:9
    },
    {
      pos:[
        2,
        0,
        13
      ],
      state:9
    },
    {
      pos:[
        2,
        0,
        14
      ],
      state:9
    },
    {
      pos:[
        2,
        0,
        15
      ],
      state:9
    },
    {
      pos:[
        2,
        0,
        16
      ],
      state:9
    },
    {
      pos:[
        2,
        0,
        17
      ],
      state:9
    },
    {
      pos:[
        2,
        0,
        18
      ],
      state:9
    },
    {
      pos:[
        2,
        0,
        19
      ],
      state:9
    },
    {
      pos:[
        3,
        0,
        0
      ],
      state:9
    },
    {
      pos:[
        3,
        0,
        1
      ],
      state:9
    },
    {
      pos:[
        3,
        0,
        2
      ],
      state:9
    },
    {
      pos:[
        3,
        0,
        3
      ],
      state:9
    },
    {
      pos:[
        3,
        0,
        4
      ],
      state:9
    },
    {
      pos:[
        3,
        0,
        5
      ],
      state:9
    },
    {
      pos:[
        3,
        0,
        6
      ],
      state:9
    },
    {
      pos:[
        3,
        0,
        7
      ],
      state:9
    },
    {
      pos:[
        3,
        0,
        8
      ],
      state:9
    },
    {
      pos:[
        3,
        0,
        9
      ],
      state:9
    },
    {
      pos:[
        3,
        0,
        10
      ],
      state:9
    },
    {
      pos:[
        3,
        0,
        11
      ],
      state:9
    },
    {
      pos:[
        3,
        0,
        12
      ],
      state:9
    },
    {
      pos:[
        3,
        0,
        13
      ],
      state:9
    },
    {
      pos:[
        3,
        0,
        14
      ],
      state:9
    },
    {
      pos:[
        3,
        0,
        15
      ],
      state:9
    },
    {
      pos:[
        3,
        0,
        16
      ],
      state:9
    },
    {
      pos:[
        3,
        0,
        17
      ],
      state:9
    },
    {
      pos:[
        3,
        0,
        19
      ],
      state:10
    },
    {
      pos:[
        4,
        0,
        0
      ],
      state:9
    },
    {
      pos:[
        4,
        0,
        1
      ],
      state:9
    },
    {
      pos:[
        4,
        0,
        2
      ],
      state:9
    },
    {
      pos:[
        4,
        0,
        3
      ],
      state:9
    },
    {
      pos:[
        4,
        0,
        4
      ],
      state:9
    },
    {
      pos:[
        4,
        0,
        5
      ],
      state:9
    },
    {
      pos:[
        4,
        0,
        6
      ],
      state:9
    },
    {
      pos:[
        4,
        0,
        7
      ],
      state:9
    },
    {
      pos:[
        4,
        0,
        8
      ],
      state:9
    },
    {
      pos:[
        4,
        0,
        9
      ],
      state:9
    },
    {
      pos:[
        4,
        0,
        10
      ],
      state:9
    },
    {
      pos:[
        4,
        0,
        11
      ],
      state:9
    },
    {
      pos:[
        4,
        0,
        12
      ],
      state:9
    },
    {
      pos:[
        4,
        0,
        13
      ],
      state:9
    },
    {
      pos:[
        4,
        0,
        14
      ],
      state:9
    },
    {
      pos:[
        4,
        0,
        15
      ],
      state:9
    },
    {
      pos:[
        4,
        0,
        16
      ],
      state:9
    },
    {
      pos:[
        4,
        0,
        17
      ],
      state:9
    },
    {
      pos:[
        4,
        0,
        18
      ],
      state:9
    },
    {
      pos:[
        4,
        0,
        19
      ],
      state:9
    },
    {
      pos:[
        5,
        0,
        0
      ],
      state:9
    },
    {
      pos:[
        5,
        0,
        1
      ],
      state:9
    },
    {
      pos:[
        5,
        0,
        2
      ],
      state:9
    },
    {
      pos:[
        5,
        0,
        3
      ],
      state:9
    },
    {
      pos:[
        5,
        0,
        4
      ],
      state:9
    },
    {
      pos:[
        5,
        0,
        5
      ],
      state:9
    },
    {
      pos:[
        5,
        0,
        6
      ],
      state:9
    },
    {
      pos:[
        5,
        0,
        7
      ],
      state:9
    },
    {
      pos:[
        5,
        0,
        8
      ],
      state:9
    },
    {
      pos:[
        5,
        0,
        9
      ],
      state:9
    },
    {
      pos:[
        5,
        0,
        10
      ],
      state:9
    },
    {
      pos:[
        5,
        0,
        11
      ],
      state:9
    },
    {
      pos:[
        5,
        0,
        12
      ],
      state:9
    },
    {
      pos:[
        5,
        0,
        13
      ],
      state:9
    },
    {
      pos:[
        5,
        0,
        14
      ],
      state:9
    },
    {
      pos:[
        5,
        0,
        15
      ],
      state:9
    },
    {
      pos:[
        5,
        0,
        16
      ],
      state:9
    },
    {
      pos:[
        5,
        0,
        17
      ],
      state:9
    },
    {
      pos:[
        5,
        0,
        18
      ],
      state:9
    },
    {
      pos:[
        5,
        0,
        19
      ],
      state:9
    },
    {
      pos:[
        6,
        0,
        0
      ],
      state:9
    },
    {
      pos:[
        6,
        0,
        1
      ],
      state:9
    },
    {
      pos:[
        6,
        0,
        2
      ],
      state:9
    },
    {
      pos:[
        6,
        0,
        3
      ],
      state:9
    },
    {
      pos:[
        6,
        0,
        4
      ],
      state:9
    },
    {
      pos:[
        6,
        0,
        5
      ],
      state:9
    },
    {
      pos:[
        6,
        0,
        6
      ],
      state:9
    },
    {
      pos:[
        6,
        0,
        7
      ],
      state:9
    },
    {
      pos:[
        6,
        0,
        8
      ],
      state:9
    },
    {
      pos:[
        6,
        0,
        9
      ],
      state:9
    },
    {
      pos:[
        6,
        0,
        10
      ],
      state:9
    },
    {
      pos:[
        6,
        0,
        11
      ],
      state:9
    },
    {
      pos:[
        6,
        0,
        12
      ],
      state:9
    },
    {
      pos:[
        6,
        0,
        13
      ],
      state:9
    },
    {
      pos:[
        6,
        0,
        14
      ],
      state:9
    },
    {
      pos:[
        6,
        0,
        15
      ],
      state:9
    },
    {
      pos:[
        6,
        0,
        16
      ],
      state:9
    },
    {
      pos:[
        6,
        0,
        17
      ],
      state:9
    },
    {
      pos:[
        6,
        0,
        18
      ],
      state:9
    },
    {
      pos:[
        6,
        0,
        19
      ],
      state:9
    },
    {
      pos:[
        7,
        0,
        0
      ],
      state:9
    },
    {
      pos:[
        7,
        0,
        1
      ],
      state:9
    },
    {
      pos:[
        7,
        0,
        2
      ],
      state:9
    },
    {
      pos:[
        7,
        0,
        3
      ],
      state:9
    },
    {
      pos:[
        7,
        0,
        4
      ],
      state:9
    },
    {
      pos:[
        7,
        0,
        5
      ],
      state:9
    },
    {
      pos:[
        7,
        0,
        6
      ],
      state:9
    },
    {
      pos:[
        7,
        0,
        7
      ],
      state:9
    },
    {
      pos:[
        7,
        0,
        8
      ],
      state:9
    },
    {
      pos:[
        7,
        0,
        9
      ],
      state:9
    },
    {
      pos:[
        7,
        0,
        10
      ],
      state:9
    },
    {
      pos:[
        7,
        0,
        11
      ],
      state:9
    },
    {
      pos:[
        7,
        0,
        12
      ],
      state:9
    },
    {
      pos:[
        7,
        0,
        13
      ],
      state:9
    },
    {
      pos:[
        7,
        0,
        14
      ],
      state:9
    },
    {
      pos:[
        7,
        0,
        15
      ],
      state:9
    },
    {
      pos:[
        7,
        0,
        16
      ],
      state:9
    },
    {
      pos:[
        7,
        0,
        17
      ],
      state:9
    },
    {
      pos:[
        7,
        0,
        18
      ],
      state:9
    },
    {
      pos:[
        7,
        0,
        19
      ],
      state:9
    },
    {
      pos:[
        8,
        0,
        0
      ],
      state:9
    },
    {
      pos:[
        8,
        0,
        1
      ],
      state:9
    },
    {
      pos:[
        8,
        0,
        2
      ],
      state:9
    },
    {
      pos:[
        8,
        0,
        3
      ],
      state:9
    },
    {
      pos:[
        8,
        0,
        4
      ],
      state:9
    },
    {
      pos:[
        8,
        0,
        5
      ],
      state:9
    },
    {
      pos:[
        8,
        0,
        6
      ],
      state:9
    },
    {
      pos:[
        8,
        0,
        7
      ],
      state:9
    },
    {
      pos:[
        8,
        0,
        8
      ],
      state:9
    },
    {
      pos:[
        8,
        0,
        9
      ],
      state:9
    },
    {
      pos:[
        8,
        0,
        10
      ],
      state:9
    },
    {
      pos:[
        8,
        0,
        11
      ],
      state:9
    },
    {
      pos:[
        8,
        0,
        12
      ],
      state:9
    },
    {
      pos:[
        8,
        0,
        13
      ],
      state:9
    },
    {
      pos:[
        8,
        0,
        14
      ],
      state:9
    },
    {
      pos:[
        8,
        0,
        15
      ],
      state:9
    },
    {
      pos:[
        8,
        0,
        16
      ],
      state:9
    },
    {
      pos:[
        8,
        0,
        17
      ],
      state:9
    },
    {
      pos:[
        8,
        0,
        18
      ],
      state:9
    },
    {
      pos:[
        8,
        0,
        19
      ],
      state:9
    },
    {
      pos:[
        9,
        0,
        0
      ],
      state:9
    },
    {
      pos:[
        9,
        0,
        1
      ],
      state:9
    },
    {
      pos:[
        9,
        0,
        2
      ],
      state:9
    },
    {
      pos:[
        9,
        0,
        3
      ],
      state:9
    },
    {
      pos:[
        9,
        0,
        4
      ],
      state:9
    },
    {
      pos:[
        9,
        0,
        5
      ],
      state:9
    },
    {
      pos:[
        9,
        0,
        6
      ],
      state:9
    },
    {
      pos:[
        9,
        0,
        7
      ],
      state:9
    },
    {
      pos:[
        9,
        0,
        8
      ],
      state:9
    },
    {
      pos:[
        9,
        0,
        11
      ],
      state:9
    },
    {
      pos:[
        9,
        0,
        12
      ],
      state:9
    },
    {
      pos:[
        9,
        0,
        13
      ],
      state:9
    },
    {
      pos:[
        9,
        0,
        14
      ],
      state:9
    },
    {
      pos:[
        9,
        0,
        15
      ],
      state:9
    },
    {
      pos:[
        9,
        0,
        16
      ],
      state:9
    },
    {
      pos:[
        9,
        0,
        17
      ],
      state:9
    },
    {
      pos:[
        9,
        0,
        18
      ],
      state:9
    },
    {
      pos:[
        9,
        0,
        19
      ],
      state:9
    },
    {
      pos:[
        10,
        0,
        0
      ],
      state:9
    },
    {
      pos:[
        10,
        0,
        1
      ],
      state:9
    },
    {
      pos:[
        10,
        0,
        2
      ],
      state:9
    },
    {
      pos:[
        10,
        0,
        3
      ],
      state:9
    },
    {
      pos:[
        10,
        0,
        4
      ],
      state:9
    },
    {
      pos:[
        10,
        0,
        5
      ],
      state:9
    },
    {
      pos:[
        10,
        0,
        6
      ],
      state:9
    },
    {
      pos:[
        10,
        0,
        7
      ],
      state:9
    },
    {
      pos:[
        10,
        0,
        8
      ],
      state:9
    },
    {
      pos:[
        10,
        0,
        11
      ],
      state:9
    },
    {
      pos:[
        10,
        0,
        12
      ],
      state:9
    },
    {
      pos:[
        10,
        0,
        13
      ],
      state:9
    },
    {
      pos:[
        10,
        0,
        14
      ],
      state:9
    },
    {
      pos:[
        10,
        0,
        15
      ],
      state:9
    },
    {
      pos:[
        10,
        0,
        16
      ],
      state:9
    },
    {
      pos:[
        10,
        0,
        17
      ],
      state:9
    },
    {
      pos:[
        10,
        0,
        18
      ],
      state:9
    },
    {
      pos:[
        10,
        0,
        19
      ],
      state:9
    },
    {
      pos:[
        11,
        0,
        0
      ],
      state:9
    },
    {
      pos:[
        11,
        0,
        1
      ],
      state:9
    },
    {
      pos:[
        11,
        0,
        2
      ],
      state:9
    },
    {
      pos:[
        11,
        0,
        3
      ],
      state:9
    },
    {
      pos:[
        11,
        0,
        4
      ],
      state:9
    },
    {
      pos:[
        11,
        0,
        5
      ],
      state:9
    },
    {
      pos:[
        11,
        0,
        6
      ],
      state:9
    },
    {
      pos:[
        11,
        0,
        7
      ],
      state:9
    },
    {
      pos:[
        11,
        0,
        8
      ],
      state:9
    },
    {
      pos:[
        11,
        0,
        9
      ],
      state:9
    },
    {
      pos:[
        11,
        0,
        10
      ],
      state:9
    },
    {
      pos:[
        11,
        0,
        11
      ],
      state:9
    },
    {
      pos:[
        11,
        0,
        12
      ],
      state:9
    },
    {
      pos:[
        11,
        0,
        13
      ],
      state:9
    },
    {
      pos:[
        11,
        0,
        14
      ],
      state:9
    },
    {
      pos:[
        11,
        0,
        15
      ],
      state:9
    },
    {
      pos:[
        11,
        0,
        16
      ],
      state:9
    },
    {
      pos:[
        11,
        0,
        17
      ],
      state:9
    },
    {
      pos:[
        11,
        0,
        18
      ],
      state:9
    },
    {
      pos:[
        11,
        0,
        19
      ],
      state:9
    },
    {
      pos:[
        12,
        0,
        0
      ],
      state:9
    },
    {
      pos:[
        12,
        0,
        1
      ],
      state:9
    },
    {
      pos:[
        12,
        0,
        2
      ],
      state:9
    },
    {
      pos:[
        12,
        0,
        3
      ],
      state:9
    },
    {
      pos:[
        12,
        0,
        4
      ],
      state:9
    },
    {
      pos:[
        12,
        0,
        5
      ],
      state:9
    },
    {
      pos:[
        12,
        0,
        6
      ],
      state:9
    },
    {
      pos:[
        12,
        0,
        7
      ],
      state:9
    },
    {
      pos:[
        12,
        0,
        8
      ],
      state:9
    },
    {
      pos:[
        12,
        0,
        9
      ],
      state:9
    },
    {
      pos:[
        12,
        0,
        10
      ],
      state:9
    },
    {
      pos:[
        12,
        0,
        11
      ],
      state:9
    },
    {
      pos:[
        12,
        0,
        12
      ],
      state:9
    },
    {
      pos:[
        12,
        0,
        13
      ],
      state:9
    },
    {
      pos:[
        12,
        0,
        14
      ],
      state:9
    },
    {
      pos:[
        12,
        0,
        15
      ],
      state:9
    },
    {
      pos:[
        12,
        0,
        16
      ],
      state:9
    },
    {
      pos:[
        12,
        0,
        17
      ],
      state:9
    },
    {
      pos:[
        12,
        0,
        18
      ],
      state:9
    },
    {
      pos:[
        12,
        0,
        19
      ],
      state:9
    },
    {
      pos:[
        0,
        1,
        0
      ],
      state:9
    },
    {
      pos:[
        9,
        1,
        9
      ],
      state:11
    },
    {
      pos:[
        9,
        1,
        10
      ],
      state:11
    },
    {
      pos:[
        10,
        1,
        9
      ],
      state:11
    },
    {
      pos:[
        10,
        1,
        10
      ],
      state:11
    },
    {
      pos:[
        0,
        2,
        0
      ],
      state:9
    },
    {
      pos:[
        1,
        2,
        7
      ],
      state:12
    },
    {
      pos:[
        1,
        2,
        8
      ],
      state:13
    },
    {
      pos:[
        1,
        2,
        9
      ],
      state:12
    },
    {
      pos:[
        1,
        2,
        10
      ],
      state:14
    },
    {
      pos:[
        1,
        2,
        11
      ],
      state:15
    },
    {
      pos:[
        1,
        2,
        12
      ],
      state:9
    },
    {
      pos:[
        1,
        2,
        13
      ],
      state:9
    },
    {
      pos:[
        2,
        2,
        2
      ],
      state:16
    },
    {
      pos:[
        2,
        2,
        3
      ],
      state:9
    },
    {
      pos:[
        2,
        2,
        4
      ],
      state:9
    },
    {
      pos:[
        2,
        2,
        5
      ],
      state:9
    },
    {
      pos:[
        2,
        2,
        7
      ],
      state:12
    },
    {
      pos:[
        2,
        2,
        8
      ],
      state:13
    },
    {
      pos:[
        2,
        2,
        9
      ],
      state:12
    },
    {
      pos:[
        2,
        2,
        10
      ],
      state:14
    },
    {
      pos:[
        2,
        2,
        11
      ],
      state:15
    },
    {
      pos:[
        2,
        2,
        12
      ],
      state:9
    },
    {
      pos:[
        2,
        2,
        13
      ],
      state:9
    },
    {
      pos:[
        2,
        2,
        15
      ],
      state:17
    },
    {
      pos:[
        2,
        2,
        16
      ],
      state:17
    },
    {
      pos:[
        2,
        2,
        17
      ],
      state:17
    },
    {
      pos:[
        3,
        2,
        2
      ],
      state:16
    },
    {
      pos:[
        3,
        2,
        3
      ],
      state:9
    },
    {
      pos:[
        3,
        2,
        4
      ],
      state:9
    },
    {
      pos:[
        3,
        2,
        5
      ],
      state:9
    },
    {
      pos:[
        3,
        2,
        7
      ],
      state:12
    },
    {
      pos:[
        3,
        2,
        8
      ],
      state:14
    },
    {
      pos:[
        3,
        2,
        9
      ],
      state:12
    },
    {
      pos:[
        3,
        2,
        10
      ],
      state:14
    },
    {
      pos:[
        3,
        2,
        11
      ],
      state:12
    },
    {
      pos:[
        3,
        2,
        12
      ],
      state:9
    },
    {
      pos:[
        3,
        2,
        13
      ],
      state:9
    },
    {
      pos:[
        3,
        2,
        14
      ],
      state:9
    },
    {
      pos:[
        3,
        2,
        15
      ],
      state:9
    },
    {
      pos:[
        3,
        2,
        16
      ],
      state:9
    },
    {
      pos:[
        3,
        2,
        17
      ],
      state:9
    },
    {
      pos:[
        3,
        2,
        18
      ],
      state:9
    },
    {
      pos:[
        4,
        2,
        2
      ],
      state:16
    },
    {
      pos:[
        4,
        2,
        3
      ],
      state:9
    },
    {
      pos:[
        4,
        2,
        4
      ],
      state:9
    },
    {
      pos:[
        4,
        2,
        5
      ],
      state:9
    },
    {
      pos:[
        4,
        2,
        7
      ],
      state:9
    },
    {
      pos:[
        4,
        2,
        8
      ],
      state:9
    },
    {
      pos:[
        4,
        2,
        9
      ],
      state:9
    },
    {
      pos:[
        4,
        2,
        10
      ],
      state:9
    },
    {
      pos:[
        4,
        2,
        11
      ],
      state:9
    },
    {
      pos:[
        4,
        2,
        12
      ],
      state:9
    },
    {
      pos:[
        4,
        2,
        13
      ],
      state:9
    },
    {
      pos:[
        4,
        2,
        14
      ],
      state:9
    },
    {
      pos:[
        4,
        2,
        15
      ],
      state:9
    },
    {
      pos:[
        4,
        2,
        16
      ],
      state:9
    },
    {
      pos:[
        4,
        2,
        17
      ],
      state:9
    },
    {
      pos:[
        4,
        2,
        18
      ],
      state:9
    },
    {
      pos:[
        5,
        2,
        2
      ],
      state:16
    },
    {
      pos:[
        5,
        2,
        3
      ],
      state:9
    },
    {
      pos:[
        5,
        2,
        4
      ],
      state:9
    },
    {
      pos:[
        5,
        2,
        5
      ],
      state:9
    },
    {
      pos:[
        5,
        2,
        7
      ],
      state:9
    },
    {
      pos:[
        5,
        2,
        8
      ],
      state:9
    },
    {
      pos:[
        5,
        2,
        9
      ],
      state:9
    },
    {
      pos:[
        5,
        2,
        10
      ],
      state:9
    },
    {
      pos:[
        5,
        2,
        11
      ],
      state:9
    },
    {
      pos:[
        5,
        2,
        12
      ],
      state:9
    },
    {
      pos:[
        5,
        2,
        13
      ],
      state:9
    },
    {
      pos:[
        5,
        2,
        14
      ],
      state:9
    },
    {
      pos:[
        5,
        2,
        15
      ],
      state:9
    },
    {
      pos:[
        5,
        2,
        16
      ],
      state:9
    },
    {
      pos:[
        5,
        2,
        17
      ],
      state:9
    },
    {
      pos:[
        5,
        2,
        18
      ],
      state:9
    },
    {
      pos:[
        6,
        2,
        1
      ],
      state:9
    },
    {
      pos:[
        6,
        2,
        2
      ],
      state:9
    },
    {
      pos:[
        6,
        2,
        3
      ],
      state:9
    },
    {
      pos:[
        6,
        2,
        4
      ],
      state:9
    },
    {
      pos:[
        6,
        2,
        5
      ],
      state:9
    },
    {
      pos:[
        6,
        2,
        6
      ],
      state:9
    },
    {
      pos:[
        6,
        2,
        7
      ],
      state:9
    },
    {
      pos:[
        6,
        2,
        8
      ],
      state:9
    },
    {
      pos:[
        6,
        2,
        9
      ],
      state:9
    },
    {
      pos:[
        6,
        2,
        10
      ],
      state:9
    },
    {
      pos:[
        6,
        2,
        11
      ],
      state:9
    },
    {
      pos:[
        6,
        2,
        12
      ],
      state:9
    },
    {
      pos:[
        6,
        2,
        13
      ],
      state:9
    },
    {
      pos:[
        6,
        2,
        14
      ],
      state:9
    },
    {
      pos:[
        6,
        2,
        15
      ],
      state:9
    },
    {
      pos:[
        6,
        2,
        16
      ],
      state:9
    },
    {
      pos:[
        6,
        2,
        17
      ],
      state:9
    },
    {
      pos:[
        6,
        2,
        18
      ],
      state:9
    },
    {
      pos:[
        7,
        2,
        1
      ],
      state:9
    },
    {
      pos:[
        7,
        2,
        2
      ],
      state:9
    },
    {
      pos:[
        7,
        2,
        3
      ],
      state:9
    },
    {
      pos:[
        7,
        2,
        4
      ],
      state:9
    },
    {
      pos:[
        7,
        2,
        5
      ],
      state:9
    },
    {
      pos:[
        7,
        2,
        6
      ],
      state:9
    },
    {
      pos:[
        7,
        2,
        7
      ],
      state:9
    },
    {
      pos:[
        7,
        2,
        8
      ],
      state:9
    },
    {
      pos:[
        7,
        2,
        9
      ],
      state:9
    },
    {
      pos:[
        7,
        2,
        10
      ],
      state:9
    },
    {
      pos:[
        7,
        2,
        11
      ],
      state:9
    },
    {
      pos:[
        7,
        2,
        12
      ],
      state:9
    },
    {
      pos:[
        7,
        2,
        14
      ],
      state:9
    },
    {
      pos:[
        7,
        2,
        15
      ],
      state:9
    },
    {
      pos:[
        7,
        2,
        16
      ],
      state:9
    },
    {
      pos:[
        7,
        2,
        17
      ],
      state:9
    },
    {
      pos:[
        7,
        2,
        18
      ],
      state:9
    },
    {
      pos:[
        8,
        2,
        1
      ],
      state:9
    },
    {
      pos:[
        8,
        2,
        2
      ],
      state:18
    },
    {
      pos:[
        8,
        2,
        3
      ],
      state:18
    },
    {
      pos:[
        8,
        2,
        4
      ],
      state:9
    },
    {
      pos:[
        8,
        2,
        5
      ],
      state:9
    },
    {
      pos:[
        8,
        2,
        6
      ],
      state:9
    },
    {
      pos:[
        8,
        2,
        8
      ],
      state:9
    },
    {
      pos:[
        8,
        2,
        9
      ],
      state:9
    },
    {
      pos:[
        8,
        2,
        10
      ],
      state:9
    },
    {
      pos:[
        8,
        2,
        11
      ],
      state:9
    },
    {
      pos:[
        8,
        2,
        14
      ],
      state:9
    },
    {
      pos:[
        8,
        2,
        15
      ],
      state:9
    },
    {
      pos:[
        8,
        2,
        16
      ],
      state:9
    },
    {
      pos:[
        8,
        2,
        17
      ],
      state:9
    },
    {
      pos:[
        8,
        2,
        18
      ],
      state:9
    },
    {
      pos:[
        9,
        2,
        1
      ],
      state:19
    },
    {
      pos:[
        9,
        2,
        2
      ],
      state:20
    },
    {
      pos:[
        9,
        2,
        3
      ],
      state:20
    },
    {
      pos:[
        9,
        2,
        4
      ],
      state:21
    },
    {
      pos:[
        9,
        2,
        5
      ],
      state:9
    },
    {
      pos:[
        9,
        2,
        6
      ],
      state:9
    },
    {
      pos:[
        9,
        2,
        7
      ],
      state:22
    },
    {
      pos:[
        9,
        2,
        8
      ],
      state:9
    },
    {
      pos:[
        9,
        2,
        9
      ],
      state:23
    },
    {
      pos:[
        9,
        2,
        10
      ],
      state:23
    },
    {
      pos:[
        9,
        2,
        11
      ],
      state:9
    },
    {
      pos:[
        9,
        2,
        12
      ],
      state:24
    },
    {
      pos:[
        9,
        2,
        14
      ],
      state:9
    },
    {
      pos:[
        9,
        2,
        15
      ],
      state:9
    },
    {
      pos:[
        9,
        2,
        16
      ],
      state:9
    },
    {
      pos:[
        9,
        2,
        17
      ],
      state:9
    },
    {
      pos:[
        9,
        2,
        18
      ],
      state:9
    },
    {
      pos:[
        10,
        2,
        1
      ],
      state:19
    },
    {
      pos:[
        10,
        2,
        2
      ],
      state:20
    },
    {
      pos:[
        10,
        2,
        3
      ],
      state:20
    },
    {
      pos:[
        10,
        2,
        4
      ],
      state:21
    },
    {
      pos:[
        10,
        2,
        5
      ],
      state:9
    },
    {
      pos:[
        10,
        2,
        6
      ],
      state:9
    },
    {
      pos:[
        10,
        2,
        8
      ],
      state:9
    },
    {
      pos:[
        10,
        2,
        9
      ],
      state:23
    },
    {
      pos:[
        10,
        2,
        10
      ],
      state:23
    },
    {
      pos:[
        10,
        2,
        11
      ],
      state:9
    },
    {
      pos:[
        10,
        2,
        14
      ],
      state:9
    },
    {
      pos:[
        10,
        2,
        15
      ],
      state:9
    },
    {
      pos:[
        10,
        2,
        16
      ],
      state:9
    },
    {
      pos:[
        10,
        2,
        17
      ],
      state:9
    },
    {
      pos:[
        10,
        2,
        18
      ],
      state:9
    },
    {
      pos:[
        11,
        2,
        1
      ],
      state:9
    },
    {
      pos:[
        11,
        2,
        2
      ],
      state:25
    },
    {
      pos:[
        11,
        2,
        3
      ],
      state:25
    },
    {
      pos:[
        11,
        2,
        4
      ],
      state:9
    },
    {
      pos:[
        11,
        2,
        5
      ],
      state:9
    },
    {
      pos:[
        11,
        2,
        6
      ],
      state:9
    },
    {
      pos:[
        11,
        2,
        7
      ],
      state:9
    },
    {
      pos:[
        11,
        2,
        8
      ],
      state:9
    },
    {
      pos:[
        11,
        2,
        9
      ],
      state:9
    },
    {
      pos:[
        11,
        2,
        10
      ],
      state:9
    },
    {
      pos:[
        11,
        2,
        11
      ],
      state:9
    },
    {
      pos:[
        11,
        2,
        12
      ],
      state:9
    },
    {
      pos:[
        11,
        2,
        14
      ],
      state:9
    },
    {
      pos:[
        11,
        2,
        15
      ],
      state:26
    },
    {
      pos:[
        11,
        2,
        16
      ],
      state:20
    },
    {
      pos:[
        11,
        2,
        17
      ],
      state:27
    },
    {
      pos:[
        11,
        2,
        18
      ],
      state:9
    },
    {
      pos:[
        0,
        3,
        0
      ],
      state:9
    },
    {
      pos:[
        1,
        3,
        2
      ],
      state:9
    },
    {
      pos:[
        1,
        3,
        3
      ],
      state:9
    },
    {
      pos:[
        1,
        3,
        4
      ],
      state:9
    },
    {
      pos:[
        1,
        3,
        5
      ],
      state:9
    },
    {
      pos:[
        1,
        3,
        7
      ],
      state:9
    },
    {
      pos:[
        1,
        3,
        8
      ],
      state:9
    },
    {
      pos:[
        1,
        3,
        9
      ],
      state:13
    },
    {
      pos:[
        1,
        3,
        10
      ],
      state:15
    },
    {
      pos:[
        1,
        3,
        11
      ],
      state:9
    },
    {
      pos:[
        1,
        3,
        12
      ],
      state:9
    },
    {
      pos:[
        1,
        3,
        13
      ],
      state:9
    },
    {
      pos:[
        1,
        3,
        14
      ],
      state:17
    },
    {
      pos:[
        1,
        3,
        15
      ],
      state:17
    },
    {
      pos:[
        1,
        3,
        16
      ],
      state:17
    },
    {
      pos:[
        1,
        3,
        17
      ],
      state:17
    },
    {
      pos:[
        1,
        3,
        18
      ],
      state:17
    },
    {
      pos:[
        2,
        3,
        2
      ],
      state:28
    },
    {
      pos:[
        2,
        3,
        3
      ],
      state:9
    },
    {
      pos:[
        2,
        3,
        4
      ],
      state:9
    },
    {
      pos:[
        2,
        3,
        5
      ],
      state:9
    },
    {
      pos:[
        2,
        3,
        7
      ],
      state:9
    },
    {
      pos:[
        2,
        3,
        8
      ],
      state:9
    },
    {
      pos:[
        2,
        3,
        9
      ],
      state:13
    },
    {
      pos:[
        2,
        3,
        10
      ],
      state:15
    },
    {
      pos:[
        2,
        3,
        11
      ],
      state:9
    },
    {
      pos:[
        2,
        3,
        12
      ],
      state:9
    },
    {
      pos:[
        2,
        3,
        13
      ],
      state:9
    },
    {
      pos:[
        2,
        3,
        14
      ],
      state:9
    },
    {
      pos:[
        2,
        3,
        15
      ],
      state:9
    },
    {
      pos:[
        2,
        3,
        16
      ],
      state:9
    },
    {
      pos:[
        2,
        3,
        17
      ],
      state:9
    },
    {
      pos:[
        2,
        3,
        18
      ],
      state:9
    },
    {
      pos:[
        3,
        3,
        2
      ],
      state:28
    },
    {
      pos:[
        3,
        3,
        3
      ],
      state:9
    },
    {
      pos:[
        3,
        3,
        4
      ],
      state:9
    },
    {
      pos:[
        3,
        3,
        5
      ],
      state:9
    },
    {
      pos:[
        3,
        3,
        7
      ],
      state:9
    },
    {
      pos:[
        3,
        3,
        8
      ],
      state:9
    },
    {
      pos:[
        3,
        3,
        9
      ],
      state:9
    },
    {
      pos:[
        3,
        3,
        10
      ],
      state:9
    },
    {
      pos:[
        3,
        3,
        11
      ],
      state:9
    },
    {
      pos:[
        3,
        3,
        12
      ],
      state:9
    },
    {
      pos:[
        3,
        3,
        13
      ],
      state:9
    },
    {
      pos:[
        3,
        3,
        14
      ],
      state:9
    },
    {
      pos:[
        3,
        3,
        15
      ],
      state:9
    },
    {
      pos:[
        3,
        3,
        16
      ],
      state:9
    },
    {
      pos:[
        3,
        3,
        17
      ],
      state:9
    },
    {
      pos:[
        3,
        3,
        18
      ],
      state:9
    },
    {
      pos:[
        4,
        3,
        2
      ],
      state:28
    },
    {
      pos:[
        4,
        3,
        3
      ],
      state:9
    },
    {
      pos:[
        4,
        3,
        4
      ],
      state:9
    },
    {
      pos:[
        4,
        3,
        5
      ],
      state:9
    },
    {
      pos:[
        4,
        3,
        7
      ],
      state:9
    },
    {
      pos:[
        4,
        3,
        8
      ],
      state:9
    },
    {
      pos:[
        4,
        3,
        9
      ],
      state:9
    },
    {
      pos:[
        4,
        3,
        10
      ],
      state:9
    },
    {
      pos:[
        4,
        3,
        11
      ],
      state:9
    },
    {
      pos:[
        4,
        3,
        12
      ],
      state:9
    },
    {
      pos:[
        4,
        3,
        13
      ],
      state:9
    },
    {
      pos:[
        4,
        3,
        14
      ],
      state:9
    },
    {
      pos:[
        4,
        3,
        15
      ],
      state:9
    },
    {
      pos:[
        4,
        3,
        16
      ],
      state:9
    },
    {
      pos:[
        4,
        3,
        17
      ],
      state:9
    },
    {
      pos:[
        4,
        3,
        18
      ],
      state:9
    },
    {
      pos:[
        5,
        3,
        2
      ],
      state:28
    },
    {
      pos:[
        5,
        3,
        3
      ],
      state:9
    },
    {
      pos:[
        5,
        3,
        4
      ],
      state:9
    },
    {
      pos:[
        5,
        3,
        5
      ],
      state:9
    },
    {
      pos:[
        5,
        3,
        6
      ],
      state:29
    },
    {
      pos:[
        5,
        3,
        7
      ],
      state:9
    },
    {
      pos:[
        5,
        3,
        8
      ],
      state:9
    },
    {
      pos:[
        5,
        3,
        9
      ],
      state:9
    },
    {
      pos:[
        5,
        3,
        10
      ],
      state:9
    },
    {
      pos:[
        5,
        3,
        11
      ],
      state:9
    },
    {
      pos:[
        5,
        3,
        12
      ],
      state:9
    },
    {
      pos:[
        5,
        3,
        13
      ],
      state:9
    },
    {
      pos:[
        5,
        3,
        14
      ],
      state:9
    },
    {
      pos:[
        5,
        3,
        15
      ],
      state:9
    },
    {
      pos:[
        5,
        3,
        16
      ],
      state:9
    },
    {
      pos:[
        5,
        3,
        17
      ],
      state:9
    },
    {
      pos:[
        5,
        3,
        18
      ],
      state:9
    },
    {
      pos:[
        6,
        3,
        1
      ],
      state:9
    },
    {
      pos:[
        6,
        3,
        2
      ],
      state:9
    },
    {
      pos:[
        6,
        3,
        3
      ],
      state:9
    },
    {
      pos:[
        6,
        3,
        4
      ],
      state:9
    },
    {
      pos:[
        6,
        3,
        5
      ],
      state:9
    },
    {
      pos:[
        6,
        3,
        6
      ],
      state:9
    },
    {
      pos:[
        6,
        3,
        7
      ],
      state:9
    },
    {
      pos:[
        6,
        3,
        8
      ],
      state:9
    },
    {
      pos:[
        6,
        3,
        9
      ],
      state:9
    },
    {
      pos:[
        6,
        3,
        10
      ],
      state:9
    },
    {
      pos:[
        6,
        3,
        11
      ],
      state:9
    },
    {
      pos:[
        6,
        3,
        12
      ],
      state:9
    },
    {
      pos:[
        6,
        3,
        13
      ],
      state:9
    },
    {
      pos:[
        6,
        3,
        14
      ],
      state:9
    },
    {
      pos:[
        6,
        3,
        15
      ],
      state:9
    },
    {
      pos:[
        6,
        3,
        16
      ],
      state:9
    },
    {
      pos:[
        6,
        3,
        17
      ],
      state:9
    },
    {
      pos:[
        6,
        3,
        18
      ],
      state:9
    },
    {
      pos:[
        7,
        3,
        1
      ],
      state:9
    },
    {
      pos:[
        7,
        3,
        2
      ],
      state:9
    },
    {
      pos:[
        7,
        3,
        3
      ],
      state:9
    },
    {
      pos:[
        7,
        3,
        4
      ],
      state:9
    },
    {
      pos:[
        7,
        3,
        5
      ],
      state:9
    },
    {
      pos:[
        7,
        3,
        6
      ],
      state:9
    },
    {
      pos:[
        7,
        3,
        7
      ],
      state:9
    },
    {
      pos:[
        7,
        3,
        8
      ],
      state:9
    },
    {
      pos:[
        7,
        3,
        9
      ],
      state:9
    },
    {
      pos:[
        7,
        3,
        10
      ],
      state:9
    },
    {
      pos:[
        7,
        3,
        11
      ],
      state:9
    },
    {
      pos:[
        7,
        3,
        12
      ],
      state:9
    },
    {
      pos:[
        7,
        3,
        14
      ],
      state:9
    },
    {
      pos:[
        7,
        3,
        15
      ],
      state:9
    },
    {
      pos:[
        7,
        3,
        16
      ],
      state:9
    },
    {
      pos:[
        7,
        3,
        17
      ],
      state:9
    },
    {
      pos:[
        7,
        3,
        18
      ],
      state:9
    },
    {
      pos:[
        8,
        3,
        1
      ],
      state:9
    },
    {
      pos:[
        8,
        3,
        2
      ],
      state:18
    },
    {
      pos:[
        8,
        3,
        3
      ],
      state:18
    },
    {
      pos:[
        8,
        3,
        4
      ],
      state:9
    },
    {
      pos:[
        8,
        3,
        5
      ],
      state:9
    },
    {
      pos:[
        8,
        3,
        6
      ],
      state:9
    },
    {
      pos:[
        8,
        3,
        7
      ],
      state:9
    },
    {
      pos:[
        8,
        3,
        8
      ],
      state:9
    },
    {
      pos:[
        8,
        3,
        9
      ],
      state:9
    },
    {
      pos:[
        8,
        3,
        10
      ],
      state:9
    },
    {
      pos:[
        8,
        3,
        11
      ],
      state:9
    },
    {
      pos:[
        8,
        3,
        12
      ],
      state:9
    },
    {
      pos:[
        8,
        3,
        14
      ],
      state:9
    },
    {
      pos:[
        8,
        3,
        15
      ],
      state:9
    },
    {
      pos:[
        8,
        3,
        16
      ],
      state:9
    },
    {
      pos:[
        8,
        3,
        17
      ],
      state:9
    },
    {
      pos:[
        8,
        3,
        18
      ],
      state:9
    },
    {
      pos:[
        9,
        3,
        1
      ],
      state:19
    },
    {
      pos:[
        9,
        3,
        4
      ],
      state:21
    },
    {
      pos:[
        9,
        3,
        5
      ],
      state:9
    },
    {
      pos:[
        9,
        3,
        6
      ],
      state:9
    },
    {
      pos:[
        9,
        3,
        7
      ],
      state:9
    },
    {
      pos:[
        9,
        3,
        8
      ],
      state:9
    },
    {
      pos:[
        9,
        3,
        9
      ],
      state:9
    },
    {
      pos:[
        9,
        3,
        10
      ],
      state:30
    },
    {
      pos:[
        9,
        3,
        11
      ],
      state:9
    },
    {
      pos:[
        9,
        3,
        12
      ],
      state:9
    },
    {
      pos:[
        9,
        3,
        14
      ],
      state:9
    },
    {
      pos:[
        9,
        3,
        15
      ],
      state:9
    },
    {
      pos:[
        9,
        3,
        16
      ],
      state:9
    },
    {
      pos:[
        9,
        3,
        17
      ],
      state:9
    },
    {
      pos:[
        9,
        3,
        18
      ],
      state:9
    },
    {
      pos:[
        10,
        3,
        1
      ],
      state:19
    },
    {
      pos:[
        10,
        3,
        4
      ],
      state:21
    },
    {
      pos:[
        10,
        3,
        5
      ],
      state:9
    },
    {
      pos:[
        10,
        3,
        6
      ],
      state:9
    },
    {
      pos:[
        10,
        3,
        7
      ],
      state:9
    },
    {
      pos:[
        10,
        3,
        8
      ],
      state:9
    },
    {
      pos:[
        10,
        3,
        9
      ],
      state:9
    },
    {
      pos:[
        10,
        3,
        10
      ],
      state:9
    },
    {
      pos:[
        10,
        3,
        11
      ],
      state:9
    },
    {
      pos:[
        10,
        3,
        12
      ],
      state:9
    },
    {
      pos:[
        10,
        3,
        14
      ],
      state:9
    },
    {
      pos:[
        10,
        3,
        15
      ],
      state:9
    },
    {
      pos:[
        10,
        3,
        16
      ],
      state:9
    },
    {
      pos:[
        10,
        3,
        17
      ],
      state:9
    },
    {
      pos:[
        10,
        3,
        18
      ],
      state:9
    },
    {
      pos:[
        11,
        3,
        1
      ],
      state:9
    },
    {
      pos:[
        11,
        3,
        2
      ],
      state:25
    },
    {
      pos:[
        11,
        3,
        3
      ],
      state:25
    },
    {
      pos:[
        11,
        3,
        4
      ],
      state:9
    },
    {
      pos:[
        11,
        3,
        5
      ],
      state:9
    },
    {
      pos:[
        11,
        3,
        6
      ],
      state:9
    },
    {
      pos:[
        11,
        3,
        7
      ],
      state:9
    },
    {
      pos:[
        11,
        3,
        8
      ],
      state:9
    },
    {
      pos:[
        11,
        3,
        9
      ],
      state:9
    },
    {
      pos:[
        11,
        3,
        10
      ],
      state:9
    },
    {
      pos:[
        11,
        3,
        11
      ],
      state:9
    },
    {
      pos:[
        11,
        3,
        12
      ],
      state:9
    },
    {
      pos:[
        11,
        3,
        14
      ],
      state:9
    },
    {
      pos:[
        11,
        3,
        18
      ],
      state:9
    },
    {
      pos:[
        0,
        4,
        0
      ],
      state:9
    },
    {
      pos:[
        1,
        4,
        2
      ],
      state:9
    },
    {
      pos:[
        1,
        4,
        3
      ],
      state:9
    },
    {
      pos:[
        1,
        4,
        4
      ],
      state:9
    },
    {
      pos:[
        1,
        4,
        5
      ],
      state:9
    },
    {
      pos:[
        1,
        4,
        6
      ],
      state:9
    },
    {
      pos:[
        1,
        4,
        7
      ],
      state:9
    },
    {
      pos:[
        1,
        4,
        8
      ],
      state:9
    },
    {
      pos:[
        1,
        4,
        9
      ],
      state:9
    },
    {
      pos:[
        1,
        4,
        10
      ],
      state:9
